Workbook

Sheet AMS
A1: AMS & SI
A3: MB/L SCAC CODE | C3: MBL NO | F3: HB/L SCAC | H3: HB/L NO. | L3: 灰色部分客户无需填写或修改
A4: VESSEL/VOYAGE | D4: POL | F4: ETD | H4: POD | J4: ETA
A5: LAST FOREIGN PORT OF LOAD | E5: FIRST U.S PORT OF DISCHARGE
A6: SHIPPER (AMS) （必填，英文，需大写）
A7: (Company Name)
A8: Address | F8: 请确认信息是否正确。
A9: City | C9: States | F9: 请参照填写说明填写
A10: zip code | C10: Country
A11: CONSIGNEE(AMS)（必填，英文，需大写）
A12: (Company Name)
A13: Address
A14: City | C14: States
A15: zip code | C15: Country
A16: NOTIFY PARTY(AMS)（必填，英文，需大写）
A17: (Company Name)
A18: Address
A19: City | C19: States
A20: zip code | C20: Country
A22: Container number | B22: Seal number | C22: 数量 | D22: 包装类型（CTN) | E22: Gross weight(kg) | F22: Volume(CBM) | G22: Cargo description （需大写） | H22: HTS code(For AMS/ISF filling) | I22: 原产地国家/Country of Origin(For ISF filling) | J22: 备注/Remark (For ISF filling) | K22: Mark&numbers | L22: 黄色必填 | M22: 灰色部分请勿修改
D23: CARTON | L23: 客户填写，具体填写方式请参照填写说明
L24: 【ISF的信息将根据您填写在AMS的内容进行代入】，请在单元格中输入数值， 勿使用公式，或者剪切方式覆盖单元格，避免破坏原表格格式，影响您ISF数据的代入。由于ISF将只发送HTS Code的前六位，将只会对您表格中填写的HTS Code自动取前六位代入。
L30: 关于Cargo description的填写提示：
L31: 自2024年4月1日起，美国海关和边境保护局（CBP）将加强对于描述模糊货物的审查。如果提供的货物描述模糊，则进口商应纠正问题，以避免受到美国海关和边境保护局（CBP）的额外审查。请注意，美国海关和边境保护局在此处提供了描述模糊货物的示例以及可接受的替代方案：https://www.cbp.gov/trade/basic-import-export/e-commerce/examples-unacceptable-vs-acceptable-cargo-descriptions。如果您还有其他问题，请咨询 AGL 操作人员。
L41: From March 1, 2023, we have stopped the IOR review and the IOR information selected when placing an online order will prevail for ISF and entry filling. If need to change IOR, you can revise it before ETD-7&CRD-5 in seller central or shipper central. 从2023年3月1号开始我们已经不会审核线下ISF文件中的IOR信息， 我们会直接使用您下单时填写的IOR 提交ISF和清关，如果需要修改IOR，您可以在ETD-7&CRD-5之前回到亚马逊后台下单界面进行修改。
L200: 需要按照品名或HTS CODE拆分数据明细后回传截单资料。

Sheet ISF
A1: 进口商安全申报Importer Security Filing (10+2) | D1: 客户无需填写在此页，卖家填写（AMS sheet） 表格后同步到此页。 此页的HTS CODE信息将根据客户填写在卖家填写（AMS sheet）界面的信息取值前六位并去掉重复的HTS CODE后用以发送ISF 信息。
A2: 美国海关关税编号/ HTSUS Number | B2: 原产地国家/ Country of Origin | C2: 备注/ Remark | D2: 1) 此页内容由贵公司提供，我司将视为真实有效，并将按照贵司所提供的内容及下单时选择的进口商信息向美国海关进行申报。
A3: =IF(Summary!E3="","",Summary!E3) | B3: =IF(Summary!J3="","",Summary!J3) | C3: =Summary!H3 | D3: 2) 如因贵司填写不真实或提供延迟而产生任何后果，均与我司无关，因此请慎重填写并按时提供以上信息，谢谢配合！
A4: =IF(Summary!E4="","",Summary!E4) | B4: =IF(Summary!J4="","",Summary!J4) | C4: =Summary!H4
A5: =IF(Summary!E5="","",Summary!E5) | B5: =IF(Summary!J5="","",Summary!J5) | C5: =Summary!H5
A6: =IF(Summary!E6="","",Summary!E6) | B6: =IF(Summary!J6="","",Summary!J6) | C6: =Summary!H6
A7: =IF(Summary!E7="","",Summary!E7) | B7: =IF(Summary!J7="","",Summary!J7) | C7: =Summary!H7
A8: =IF(Summary!E8="","",Summary!E8) | B8: =IF(Summary!J8="","",Summary!J8) | C8: =Summary!H8
A9: =IF(Summary!E9="","",Summary!E9) | B9: =IF(Summary!J9="","",Summary!J9) | C9: =Summary!H9
A10: =IF(Summary!E10="","",Summary!E10) | B10: =IF(Summary!J10="","",Summary!J10) | C10: =Summary!H10
A11: =IF(Summary!E11="","",Summary!E11) | B11: =IF(Summary!J11="","",Summary!J11) | C11: =Summary!H11
A12: =IF(Summary!E12="","",Summary!E12) | B12: =IF(Summary!J12="","",Summary!J12) | C12: =Summary!H12
A13: =IF(Summary!E13="","",Summary!E13) | B13: =IF(Summary!J13="","",Summary!J13) | C13: =Summary!H13
A14: =IF(Summary!E14="","",Summary!E14) | B14: =IF(Summary!J14="","",Summary!J14) | C14: =Summary!H14
A15: =IF(Summary!E15="","",Summary!E15) | B15: =IF(Summary!J15="","",Summary!J15) | C15: =Summary!H15
... A1000: =IF(Summary!E1000="","",Summary!E1000) | B1000: =IF(Summary!J1000="","",Summary!J1000) | C1000: =Summary!H1000

Sheet Summary
A1: 进口商安全申报Importer Security Filing (10+2)
A2: 美国海关关税编号/ HTSUS Number | B2: HTSUS Number*6 | C2: 去重 | F2: 原产地国家/ Country of Origin | G2: 备注/ Remark
A3: =IF(AMS!H23="","",AMS!H23) | B3: =IF(A3<>"",IFERROR(IF(SEARCH(".",A3),LEFT(SUBSTITUTE(A3,".",""),6)),LEFT(SUBSTITUTE(SUBSTITUTE(TRIM(A3)," ","")," ",""),6)),"") | C3: {=IFERROR(INDEX(Summary!$I$3:$I$1000,SMALL((Summary!$I$3:$I$1000="")/0.1%+ROW($3:$1000),ROW()-2)-2)&"","")} | D3: {=IFERROR(INDEX(Summary!$C$3:$C$1000,SMALL(IF(MATCH(Summary!C3:C1000,Summary!C3:C1000,0)=ROW(Summary!C3:C1000)-2,ROW(Summary!C3:C1000)-2,7200),ROW(Summary!C3:C1000)-2)),"")} | E3: =LEFT(D3,6) | F3: =IF(AMS!I23="","",AMS!I23) | G3: =IF(AMS!J23="","",AMS!J23) | H3: {=IF(A3<>" ",IFERROR(INDEX(Summary!$G$3:$G$1000,SMALL((Summary!$G$3:$G$1000="")/0.1%+ROW($3:$1000),ROW()-2)-2)&"",""),"")} | I3: =B3&F3 | J3: =IF(D3="","",RIGHT(D3,LEN(D3)-6))
A4: =IF(AMS!H24="","",AMS!H24) | B4: =IF(A4<>"",IFERROR(IF(SEARCH(".",A4),LEFT(SUBSTITUTE(A4,".",""),6)),LEFT(SUBSTITUTE(SUBSTITUTE(TRIM(A4)," ","")," ",""),6)),"") | C4: {=IFERROR(INDEX(Summary!$I$3:$I$1000,SMALL((Summary!$I$3:$I$1000="")/0.1%+ROW($3:$1000),ROW()-2)-2)&"","")} | E4: =LEFT(D4,6) | F4: =IF(AMS!I24="","",AMS!I24) | G4: =IF(AMS!J24="","",AMS!J24) | H4: {=IF(A4<>" ",IFERROR(INDEX(Summary!$G$3:$G$1000,SMALL((Summary!$G$3:$G$1000="")/0.1%+ROW($3:$1000),ROW()-2)-2)&"",""),"")} | I4: =B4&F4 | J4: =IF(D4="","",RIGHT(D4,LEN(D4)-6))
A5: =IF(AMS!H25="","",AMS!H25) | B5: =IF(A5<>"",IFERROR(IF(SEARCH(".",A5),LEFT(SUBSTITUTE(A5,".",""),6)),LEFT(SUBSTITUTE(SUBSTITUTE(TRIM(A5)," ","")," ",""),6)),"") | C5: {=IFERROR(INDEX(Summary!$I$3:$I$1000,SMALL((Summary!$I$3:$I$1000="")/0.1%+ROW($3:$1000),ROW()-2)-2)&"","")} | E5: =LEFT(D5,6) | F5: =IF(AMS!I25="","",AMS!I25) | G5: =IF(AMS!J25="","",AMS!J25) | H5: {=IF(A5<>" ",IFERROR(INDEX(Summary!$G$3:$G$1000,SMALL((Summary!$G$3:$G$1000="")/0.1%+ROW($3:$1000),ROW()-2)-2)&"",""),"")} | I5: =B5&F5 | J5: =IF(D5="","",RIGHT(D5,LEN(D5)-6))
A6: =IF(AMS!H26="","",AMS!H26) | B6: =IF(A6<>"",IFERROR(IF(SEARCH(".",A6),LEFT(SUBSTITUTE(A6,".",""),6)),LEFT(SUBSTITUTE(SUBSTITUTE(TRIM(A6)," ","")," ",""),6)),"") | C6: {=IFERROR(INDEX(Summary!$I$3:$I$1000,SMALL((Summary!$I$3:$I$1000="")/0.1%+ROW($3:$1000),ROW()-2)-2)&"","")} | E6: =LEFT(D6,6) | F6: =IF(AMS!I26="","",AMS!I26) | G6: =IF(AMS!J26="","",AMS!J26) | H6: {=IF(A6<>" ",IFERROR(INDEX(Summary!$G$3:$G$1000,SMALL((Summary!$G$3:$G$1000="")/0.1%+ROW($3:$1000),ROW()-2)-2)&"",""),"")} | I6: =B6&F6 | J6: =IF(D6="","",RIGHT(D6,LEN(D6)-6))
A7: =IF(AMS!H27="","",AMS!H27) | B7: =IF(A7<>"",IFERROR(IF(SEARCH(".",A7),LEFT(SUBSTITUTE(A7,".",""),6)),LEFT(SUBSTITUTE(SUBSTITUTE(TRIM(A7)," ","")," ",""),6)),"") | C7: {=IFERROR(INDEX(Summary!$I$3:$I$1000,SMALL((Summary!$I$3:$I$1000="")/0.1%+ROW($3:$1000),ROW()-2)-2)&"","")} | E7: =LEFT(D7,6) | F7: =IF(AMS!I27="","",AMS!I27) | G7: =IF(AMS!J27="","",AMS!J27) | H7: {=IF(A7<>" ",IFERROR(INDEX(Summary!$G$3:$G$1000,SMALL((Summary!$G$3:$G$1000="")/0.1%+ROW($3:$1000),ROW()-2)-2)&"",""),"")} | I7: =B7&F7 | J7: =IF(D7="","",RIGHT(D7,LEN(D7)-6))
A8: =IF(AMS!H28="","",AMS!H28) | B8: =IF(A8<>"",IFERROR(IF(SEARCH(".",A8),LEFT(SUBSTITUTE(A8,".",""),6)),LEFT(SUBSTITUTE(SUBSTITUTE(TRIM(A8)," ","")," ",""),6)),"") | C8: {=IFERROR(INDEX(Summary!$I$3:$I$1000,SMALL((Summary!$I$3:$I$1000="")/0.1%+ROW($3:$1000),ROW()-2)-2)&"","")} | E8: =LEFT(D8,6) | F8: =IF(AMS!I28="","",AMS!I28) | G8: =IF(AMS!J28="","",AMS!J28) | H8: {=IF(A8<>" ",IFERROR(INDEX(Summary!$G$3:$G$1000,SMALL((Summary!$G$3:$G$1000="")/0.1%+ROW($3:$1000),ROW()-2)-2)&"",""),"")} | I8: =B8&F8 | J8: =IF(D8="","",RIGHT(D8,LEN(D8)-6))
A9: =IF(AMS!H29="","",AMS!H29) | B9: =IF(A9<>"",IFERROR(IF(SEARCH(".",A9),LEFT(SUBSTITUTE(A9,".",""),6)),LEFT(SUBSTITUTE(SUBSTITUTE(TRIM(A9)," ","")," ",""),6)),"") | C9: {=IFERROR(INDEX(Summary!$I$3:$I$1000,SMALL((Summary!$I$3:$I$1000="")/0.1%+ROW($3:$1000),ROW()-2)-2)&"","")} | E9: =LEFT(D9,6) | F9: =IF(AMS!I29="","",AMS!I29) | G9: =IF(AMS!J29="","",AMS!J29) | H9: {=IF(A9<>" ",IFERROR(INDEX(Summary!$G$3:$G$1000,SMALL((Summary!$G$3:$G$1000="")/0.1%+ROW($3:$1000),ROW()-2)-2)&"",""),"")} | I9: =B9&F9 | J9: =IF(D9="","",RIGHT(D9,LEN(D9)-6))
A10: =IF(AMS!H30="","",AMS!H30) | B10: =IF(A10<>"",IFERROR(IF(SEARCH(".",A10),LEFT(SUBSTITUTE(A10,".",""),6)),LEFT(SUBSTITUTE(SUBSTITUTE(TRIM(A10)," ","")," ",""),6)),"") | C10: {=IFERROR(INDEX(Summary!$I$3:$I$1000,SMALL((Summary!$I$3:$I$1000="")/0.1%+ROW($3:$1000),ROW()-2)-2)&"","")} | E10: =LEFT(D10,6) | F10: =IF(AMS!I30="","",AMS!I30) | G10: =IF(AMS!J30="","",AMS!J30) | H10: {=IF(A10<>" ",IFERROR(INDEX(Summary!$G$3:$G$1000,SMALL((Summary!$G$3:$G$1000="")/0.1%+ROW($3:$1000),ROW()-2)-2)&"",""),"")} | I10: =B10&F10 | J10: =IF(D10="","",RIGHT(D10,LEN(D10)-6))
A11: =IF(AMS!H31="","",AMS!H31) | B11: =IF(A11<>"",IFERROR(IF(SEARCH(".",A11),LEFT(SUBSTITUTE(A11,".",""),6)),LEFT(SUBSTITUTE(SUBSTITUTE(TRIM(A11)," ","")," ",""),6)),"") | C11: {=IFERROR(INDEX(Summary!$I$3:$I$1000,SMALL((Summary!$I$3:$I$1000="")/0.1%+ROW($3:$1000),ROW()-2)-2)&"","")} | E11: =LEFT(D11,6) | F11: =IF(AMS!I31="","",AMS!I31) | G11: =IF(AMS!J31="","",AMS!J31) | H11: {=IF(A11<>" ",IFERROR(INDEX(Summary!$G$3:$G$1000,SMALL((Summary!$G$3:$G$1000="")/0.1%+ROW($3:$1000),ROW()-2)-2)&"",""),"")} | I11: =B11&F11 | J11: =IF(D11="","",RIGHT(D11,LEN(D11)-6))
A12: =IF(AMS!H32="","",AMS!H32) | B12: =IF(A12<>"",IFERROR(IF(SEARCH(".",A12),LEFT(SUBSTITUTE(A12,".",""),6)),LEFT(SUBSTITUTE(SUBSTITUTE(TRIM(A12)," ","")," ",""),6)),"") | C12: {=IFERROR(INDEX(Summary!$I$3:$I$1000,SMALL((Summary!$I$3:$I$1000="")/0.1%+ROW($3:$1000),ROW()-2)-2)&"","")} | E12: =LEFT(D12,6) | F12: =IF(AMS!I32="","",AMS!I32) | G12: =IF(AMS!J32="","",AMS!J32) | H12: {=IF(A12<>" ",IFERROR(INDEX(Summary!$G$3:$G$1000,SMALL((Summary!$G$3:$G$1000="")/0.1%+ROW($3:$1000),ROW()-2)-2)&"",""),"")} | I12: =B12&F12 | J12: =IF(D12="","",RIGHT(D12,LEN(D12)-6))
A13: =IF(AMS!H33="","",AMS!H33) | B13: =IF(A13<>"",IFERROR(IF(SEARCH(".",A13),LEFT(SUBSTITUTE(A13,".",""),6)),LEFT(SUBSTITUTE(SUBSTITUTE(TRIM(A13)," ","")," ",""),6)),"") | C13: {=IFERROR(INDEX(Summary!$I$3:$I$1000,SMALL((Summary!$I$3:$I$1000="")/0.1%+ROW($3:$1000),ROW()-2)-2)&"","")} | E13: =LEFT(D13,6) | F13: =IF(AMS!I33="","",AMS!I33) | G13: =IF(AMS!J33="","",AMS!J33) | H13: {=IF(A13<>" ",IFERROR(INDEX(Summary!$G$3:$G$1000,SMALL((Summary!$G$3:$G$1000="")/0.1%+ROW($3:$1000),ROW()-2)-2)&"",""),"")} | I13: =B13&F13 | J13: =IF(D13="","",RIGHT(D13,LEN(D13)-6))
A14: =IF(AMS!H34="","",AMS!H34) | B14: =IF(A14<>"",IFERROR(IF(SEARCH(".",A14),LEFT(SUBSTITUTE(A14,".",""),6)),LEFT(SUBSTITUTE(SUBSTITUTE(TRIM(A14)," ","")," ",""),6)),"") | C14: {=IFERROR(INDEX(Summary!$I$3:$I$1000,SMALL((Summary!$I$3:$I$1000="")/0.1%+ROW($3:$1000),ROW()-2)-2)&"","")} | E14: =LEFT(D14,6) | F14: =IF(AMS!I34="","",AMS!I34) | G14: =IF(AMS!J34="","",AMS!J34) | H14: {=IF(A14<>" ",IFERROR(INDEX(Summary!$G$3:$G$1000,SMALL((Summary!$G$3:$G$1000="")/0.1%+ROW($3:$1000),ROW()-2)-2)&"",""),"")} | I14: =B14&F14 | J14: =IF(D14="","",RIGHT(D14,LEN(D14)-6))
A15: =IF(AMS!H35="","",AMS!H35) | B15: =IF(A15<>"",IFERROR(IF(SEARCH(".",A15),LEFT(SUBSTITUTE(A15,".",""),6)),LEFT(SUBSTITUTE(SUBSTITUTE(TRIM(A15)," ","")," ",""),6)),"") | C15: {=IFERROR(INDEX(Summary!$I$3:$I$1000,SMALL((Summary!$I$3:$I$1000="")/0.1%+ROW($3:$1000),ROW()-2)-2)&"","")} | E15: =LEFT(D15,6) | F15: =IF(AMS!I35="","",AMS!I35) | G15: =IF(AMS!J35="","",AMS!J35) | H15: {=IF(A15<>" ",IFERROR(INDEX(Summary!$G$3:$G$1000,SMALL((Summary!$G$3:$G$1000="")/0.1%+ROW($3:$1000),ROW()-2)-2)&"",""),"")} | I15: =B15&F15 | J15: =IF(D15="","",RIGHT(D15,LEN(D15)-6))
... A1000: =IF(AMS!H1020="","",AMS!H1020) | B1000: =IF(A1000<>"",IFERROR(IF(SEARCH(".",A1000),LEFT(SUBSTITUTE(A1000,".",""),6)),LEFT(SUBSTITUTE(SUBSTITUTE(TRIM(A1000)," ","")," ",""),6)),"") | C1000: {=IFERROR(INDEX(Summary!$I$3:$I$1000,SMALL((Summary!$I$3:$I$1000="")/0.1%+ROW($3:$1000),ROW()-2)-2)&"","")} | E1000: =LEFT(D1000,6) | F1000: =IF(AMS!I1020="","",AMS!I1020) | G1000: =IF(AMS!J1020="","",AMS!J1020) | H1000: {=IF(A1000<>" ",IFERROR(INDEX(Summary!$G$3:$G$1000,SMALL((Summary!$G$3:$G$1000="")/0.1%+ROW($3:$1000),ROW()-2)-2)&"",""),"")} | I1000: =B1000&F1000 | J1000: =IF(D1000="","",RIGHT(D1000,LEN(D1000)-6))

Sheet 填写说明 
A1: AMS & SI
A3: MB/L SCAC CODE | B3: 无需填写 | C3: MBL NO | D3: 无需填写 | F3: HB/L SCAC | G3: 无需填写 | H3: HB/L NO. | I3: 无需填写
A4: VESSEL/VOYAGE | B4: 无需填写 | D4: POL | E4: 无需填写 | F4: ETD | G4: 无需填写 | H4: POD | I4: 无需填写 | J4: ETA | K4: 无需填写
A5: LAST FOREIGN PORT OF LOAD | C5: 无需填写 | E5: FIRST U.S PORT OF DISCHARGE | G5: 无需填写
A6: SHIPPER (AMS) （发货人，需大写） | F6: SHIPPER( AMAZON B/L)
A7: (Company Name)公司名 | B7: 填写发货公司（有多种情况，但不限于：填写卖家自己的公司，填写工厂对应的公司，填写外贸公司） | F7: (Company Name) | G7: 和左边AMS信息相同,可以不填写
A8: Address（地址） | B8: 填写上方公司对应的地址 | F8: (Address 1) | G8: 和左边AMS信息相同,可以不填写
A9: City(城市) | B9: 对应以上地址的城市（例如XIAMEN） | C9: States(省份) | D9: 对应以上地址的省份（例如FUJIAN） | F9: (Address 2)
A10: zip code（邮编） | B10: 对应以上地址的的邮编（例如361000 | C10: Country（国家） | D10: CN | F10: (Address 3)
A11: CONSIGNEE(AMS)（收货人，需大写） | F11: CONSIGNEE( AMAZON B/L)
A12: (Company Name) | B12: 填写Bond上的公司名称+ C/O FBA （例如：IND9 仓库,应该填写为： ABC COMPANY C/O FBA） | F12: (Company Name) | G12: 和左边AMS信息相同,可以不填写
A13: Address | B13: 已根据目的港仓库的实时情况，安排到最优的FC，请勿修改（可能与订舱FC不一致）。 | F13: (Address 1) | G13: 和左边AMS信息相同,可以不填写
A14: City | B14: 对应以上地址的城市（例如SAN BERNARDINO） | C14: States | D14: 对应以上地址的州代码（例如，CA） | F14: (Address 2)
A15: zip code | B15: 对应以上地址的的邮编（例如，92407） | C15: Country | D15: US | F15: (Address 3)
A16: NOTIFY PARTY(AMS)（通知方，需大写） | F16: NOTIFY PARTY ( AMAZON B/L）
A17: (Company Name) | B17: 已预填该票货物对应的 FC仓库名称（例如：GOLDEN STATE FC LLC）； | F17: (Company Name) | G17: 和左边AMS信息相同,可以不填写
A18: Address | B18: 已预填FC仓库地址 | F18: (Address 1) | G18: 和左边AMS信息相同,可以不填写
A19: City | B19: 对应以上地址的城市（例如,SAN BERNARDINO） | C19: States | D19: 对应以上地址的州代码（例如，CA) | F19: (Address 2)
A20: zip code | B20: 对应以上地址的的邮编（例如，92407） | C20: Country | D20: US | F20: (Address 3)
A22: Container number | B22: Seal number | C22: 数量 | D22: 包装类型（CTNS) | E22: Gross weight(kg) | F22: Volume(CBM) | G22: Cargo description （需大写） | H22: HTS code(For AMS/ISF filling) | I22: 原产地国家/Country of Origin(For ISF filling) | J22: 备注/Remark (For ISF filling) | K22: Mark&numbers
C23: 入仓总数量，如需复量，请复量之后填写实际数据 | D23: 外包装件数，一般指纸箱，与报关单上的单位，数量一致。 | E23: 如果有多个HTS code， 需要分行填写每个HTS code对应的重量，拆分后的总毛重请与报关资料毛重保持一致。 | F23: 入仓总体积，如需复量，请复量之后填写实际数据;如果有多个HTS code， 需要分行填写每个HTS code对应的体积 | G23: 1.英文货物品名 2.上海和宁波必须和报关品名保持一致 3.多品名请分行填写并一 一对应HTS CODE | H23: 海关编码，保留HTS code 前6位数字，不能保存标点符号 | I23: 根据货物原产地情况填写 | J23: 比如，是否 301豁免. 如果没有无需备注 | K23: 有唛头就按照实际，没有唛头就写：N/M
A30: 请注意，根据上海美线船公司要求，如多品名或多HTS CODE，需要按照品名或HTS CODE拆分数据明细后回传截单资料。

Sheet English Instructions
A1: AMS & SI
A3: MB/L SCAC CODE | B3: No need to fill in | C3: MBL NO | D3: No need to fill in | F3: HB/L SCAC | G3: No need to fill in | H3: HB/L NO. | I3: No need to fill in
A4: VESSEL/VOYAGE | B4: No need to fill in | D4: POL | E4: No need to fill in | F4: ETD | G4: No need to fill in | H4: POD | I4: No need to fill in | J4: ETA | K4: No need to fill in
A5: LAST FOREIGN PORT OF LOAD | C5: No need to fill in | E5: FIRST U.S PORT OF DISCHARGE | G5: No need to fill in
A6: SHIPPER (AMS) (Capitalization is required) | F6: SHIPPER( AMAZON B/L)
A7: Company Name | B7: Shipper company name | F7: (Company Name) | G7: Same as the left information
A8: Address | B8: The address corresponding to the company above | F8: (Address 1) | G8: Same as the left information
A9: City | B9: The city of the corresponding to the company above | C9: States | D9: The Province of the corresponding to the company above | F9: (Address 2)
A10: zip code | B10: The Postal Code of the corresponding to the company above | C10: Country | D10: CN | F10: (Address 3)
A11: CONSIGNEE (AMS) (Capitalization is required) | F11: CONSIGNEE( AMAZON B/L)
A12: Company Name | B12: Company Name on Bond + C/O FBA (For example: ABC COMPANY C/O FBA) | F12: (Company Name) | G12: Same as the left information
A13: Address | B13: The optimal FC has been arranged according to the real-time situation of the FC in the destination, please do not modify (may not be consistent with the booking FC) | F13: (Address 1) | G13: Same as the left information
A14: City | B14: The city of the FBA warehouse | C14: States | D14: The State code of the FBA warehouse | F14: (Address 2)
A15: zip code | B15: The Postal Code of the FBA warehouse | C15: Country | D15: The Country of the FBA warehouse | F15: (Address 3)
A16: NOTIFY PARTY (AMS) (Capitalization is required) | F16: NOTIFY PARTY ( AMAZON B/L）
A17: Company Name | B17: The FBA warehouse name (For example：GOLDEN STATE FC LLC) | F17: (Company Name) | G17: Same as the left information
A18: Address | B18: The FBA warehouse address | F18: (Address 1) | G18: Same as the left information
A19: City | B19: The city of the FBA warehouse | C19: States | D19: The State code of the FBA warehouse | F19: (Address 2)
A20: zip code | B20: The Postal Code of the FBA warehouse | C20: Country | D20: The Country of the FBA warehouse | F20: (Address 3)
A22: Container number | B22: Seal number | C22: Carton | D22: Package type | E22: Gross weight(kg) | F22: Volume(CBM) | G22: Cargo description (Capitalization is required) | H22: HTS code(For AMS/ISF filling) | I22: Country of Origin(For ISF filling) | J22: Remark(For ISF filling) | K22: Mark&numbers
A23: Not required | B23: Not required | C23: The total number of cartons(or packages) delivered to warehouse, if you need to remeasure, please fill in the actual carton after remeasurement. | D23: Number of outer packaging pieces, generally referring to cardboard boxes:CARTON.The number shouble be the same as "Manifest Quantity" on the Entry Summary. | E23: Actual cargo gross weight | F23: The total volume of cargo delivered to warehouse, if you need to remeasure, please fill in the actual CBM after remeasurement. | G23: Cargo description (For shipment from Shanghai,Ningbo: Cargo description must be consistent with the cargo description declared at customs.) | H23: Enter the HTS code, which will be 6 digits. (Punctuation cannot be saved.) | I23: Fill in according to the origin of the goods | K23: Enter the shipping mark.If there is no shipping mark, enter "N/M”

Sheet FC ADDRESS
A1: FC | B1: POD | C1: COMPANY_NAME | D1: ADDRESS | E1: CITY | F1: STATES | G1: POSTAL_CODE | H1: COUNTRY | I1: TYPE
A2: ABE3 | B2: USNYC | C2: AMAZON.COM.DEDC, INC | D2: 650 BOULDER DRIVE | E2: BREINIGSVILLE | F2: PA | G2: 18031 | H2: US | I2: Shoes
A3: ABE4 | B3: USNYC | C3: Amazon.com.dedc LLC | D3: 1610 Van Buren Road | E3: Easton | F3: PA | G3: 18045 | H3: US | I3: NonSort
A4: ACY2 | B4: USNYC | C4: Amazon.com Services, Inc | D4: 1101 E PEARL ST | E4: BURLINGTON | F4: NJ | G4: 08016 | H4: US | I4: NonSort
A5: AVP3 | B5: USNYC | C5: Amazon.com.dedc LLC | D5: 298 1ST AVE | E5: GOULDSBORO | F5: PA | G5: 18424 | H5: US | I5: HB
A6: BWI4 | B6: USBWI | C6: Amazon.com.kydc LLC | D6: 165 Business Blvd | E6: Clear Brook | F6: VA | G6: 22624 | H6: US | I6: NonSort
A7: DCA6 | B7: USBWI | C7: AMAZON.COM.DEDC LLC | D7: 6001 BETHLEHEM BLVD | E7: Baltimore | F7: MD | G7: 21219 | H7: US | I7: NonSort
A8: FTW2 | B8: USDAL | C8: AMAZON.COM.KYDC LLC | D8: 2701 WEST BETHEL ROAD | E8: COPPELL | F8: TX | G8: 75019 | H8: US | I8: HB
A9: GSP1 | B9: USSAV | C9: GOLDEN STATE FC LLC | D9: 402 JOHN DODD RD | E9: SPARTANBURG | F9: SC | G9: 29303 | H9: US | I9: NonSort
A10: HOU3 | B10: USHOU | C10: AMAZON.COM.KYDC LLC | D10: 31555 HIGHWAY 90 E | E10: BROOKSHIRE | F10: TX | G10: 77423 | H10: US | I10: NonSort
A11: HOU7 | B11: USHOU | C11: Amazon.com Services INC. | D11: 16225 TOMBALL PKWY BLDG A | E11: HOUSTON | F11: TX | G11: 77064 | H11: US | I11: HB
A12: HOU8 | B12: USHOU | C12: Amazon.com Services LLC | D12: 2303 Hurricane Lane | E12: FRESNO | F12: TX | G12: 77545 | H12: US | I12: NonSort
... A55: MCE1 | B55: USOAK | C55: Amazon.com Services LLC | D55: 3200 Fulkerth Road | E55: TURLOCK | F55: CA | G55: 95380-9684 | H55: US | I55: NonSort
A56: XLX3 | B56: USLAX | C56: Amazon.com Services LLC | D56: 21590 Needham Ranch Parkway | E56: Santa Clarita | F56: CA | G56: 91321 | H56: US | I56: Sort
A57: SCK8 | B57: USOAK | C57: Amazon.com Services LLC | D57: 4700 WILBUR AVE | E57: OAKLEY | F57: CA | G57: 94561-2677 | H57: US | I57: Sort
A58: XCH1 | B58: USHOU | C58: Amazon.com Services LLC | D58: 5800 Mesa Dr | E58: Houston | F58: TX | G58: 77028 | H58: US | I58: NonSort
A59: IUSV | B59: USLAX | C59: Amazon.com Services LLC | D59: 1901 California St | E59: REDLANDS | F59: CA | G59: 92374-5015 | H59: US | I59: STAR | J59: AWD
A60: GEU2 | B60: USLAX | C60: Amazon.com Services LLC | D60: 15301 W Northern Ave Litchfield Park | E60: Litchfield Park | F60: AZ | G60: 85340 | H60: US | I60: Sort | J60: AMP/MSS (nIXD)
A61: GEU3 | B61: USLAX | C61: Amazon.com Services LLC | D61: 18900 W McDowell Road | E61: BUCKEYE | F61: AZ | G61: 85396 | H61: US | I61: Sort | J61: AMP/MSS (nIXD)
A62: GEU5 | B62: USLAX | C62: Amazon.com Services LLC | D62: 4660 N Cotton LN | E62: GOODYEAR | F62: AZ | G62: 85395 | H62: US | I62: Sort | J62: AMP/MSS (nIXD)
A63: IUSJ | B63: USLAX | C63: Amazon.com Services LLC | D63: 36900 W 4th St | E63: Beaumont | F63: CA | G63: 92223 | H63: US | I63: STAR | J63: AWD | K63: WEST
A64: IUSP | B64: USLAX | C64: Amazon.com Services LLC | D64: 8140 Caliente Rd | E64: HESPERIA | F64: CA | G64: 92344 | H64: US | I64: STAR | J64: AWD | K64: WEST
A65: IUSQ | B65: USLAX | C65: Amazon.com Services LLC | D65: 2125 West San Bernardino Ave Redlands , CA 92374 | E65: Redlands | F65: CA | G65: 92374 | H65: US | I65: STAR | J65: AWD | K65: WEST
A66: IUSW | B66: USLAX | C66: Amazon.com Services LLC | D66: 8130 Caliente Rd | E66: Hesperia | F66: CA | G66: 92344 | H66: US | I66: STAR | J66: AWD | K66: WEST_PALLETS
A67: IUTE | B67: USLAX | C67: Amazon.com Services LLC | D67: 16155 W Elwood St | E67: GOODYEAR | F67: AZ | G67: 85338 | H67: US | I67: STAR | J67: AWD | K67: WEST_PALLETS
A68: IUTF | B68: USLAX | C68: Amazon.com Services LLC | D68: 4375 North Perris Boulevard | E68: PERRIS | F68: CA | G68: 92571-7901 | H68: US | I68: STAR | J68: AWD | K68: WEST
A69: LAS1 | B69: USLAX | C69: Amazon.com Services, Inc. | D69: 12300 Bermuda Road | E69: Henderson | F69: NV | G69: 89044 | H69: US | I69: Sort | J69: SMP/GWD/AMP 2.0 (rIXD) | K69: NORTH_CENTRAL
A70: LAX9 | B70: USLAX | C70: Amazon.com Services, Inc. | D70: 11263 Oleander Ave | E70: FONTANA | F70: CA | G70: 92337-7441 | H70: US | I70: Sort | J70: SMP/GWD/AMP 2.0 (rIXD) | K70: SOUTH_CENTRAL
A71: LGB8 | B71: USLAX | C71: Amazon.com Services, Inc. | D71: 1568 N Linden Ave | E71: Rialto | F71: CA | G71: 92376-8624 | H71: US | I71: Sort | J71: SMP/GWD/AMP 2.0 (rIXD) | K71: WEST
A72: MIT2 | B72: USLAX | C72: Amazon.com Services LLC | D72: 5408 Express Avenue | E72: Shafter | F72: CA | G72: 93263 | H72: US | I72: Sort | J72: AMP/MSS (nIXD)
A73: ONT8 | B73: USLAX | C73: Amazon.com Services, Inc. | D73: 24300 Nandina Ave | E73: MORENO VALLEY | F73: CA | G73: 92551-9534 | H73: US | I73: Sort | J73: SMP/GWD/AMP 2.0 (rIXD) | K73: WEST
A74: POC1 | B74: USLAX | C74: Amazon.com Services LLC | D74: 4121 Coyote Canyon Road | E74: Fontana | F74: CA | G74: 92336 | H74: US | I74: Sort | J74: AMP/MSS (nIXD) | K74: WEST
A75: POC2 | B75: USLAX | C75: Amazon.com Services LLC | D75: 4000 South Hamner Avenue, | E75: Ontario | F75: CA | G75: 91761 | H75: US | I75: Sort | J75: AMP/MSS (nIXD) | K75: WEST
A76: POC3 | B76: USLAX | C76: Amazon.com Services LLC | D76: 6120 Clinker Drive, | E76: Jurupa Valley | F76: CA | G76: 92509 | H76: US | I76: Sort | J76: AMP/MSS (nIXD) | K76: WEST
A77: PSP3 | B77: USLAX | C77: Amazon.com Services LLC | D77: 64165 19th AVE,DESERT HOT SPRINGS | E77: DESERT HOT SPRINGS | F77: CA | G77: 92240 | H77: US | I77: Sort | J77: SMP/GWD/AMP 2.0 (rIXD) | K77: SOUTH_CENTRAL
A78: QXY2 | B78: USLAX | C78: Amazon.com Services LLC | D78: 18580 GATEWAY DR | E78: VICTORVILLE | F78: CA | G78: 92394 | H78: US | I78: HeavyBulky | J78: MSS | K78: WEST
A79: QXY8 | B79: USLAX | C79: Amazon.com Services LLC | D79: 3611 S NORTHPOINTE DR FRESNO, CA 93725-1962 | E79: Fresno | F79: CA | G79: 93725 | H79: US | I79: Sort | J79: AMP/MSS (nIXD)
A80: SBD1 | B80: USLAX | C80: Amazon.com Services LLC | D80: 3388 S Cactus Ave | E80: BLOOMINGTON | F80: CA | G80: 92316-3819 | H80: US | I80: Sort | J80: SMP/GWD/AMP 2.0 (rIXD) | K80: WEST
A81: SBD3 | B81: USLAX | C81: Amazon.com Services LLC | D81: 5990 N Cajon Blvd | E81: San Bernardino | F81: CA | G81: 92407-1833 | H81: US | I81: NonSort | J81: AMP/MSS (1P IPC) | K81: WEST
A82: VGT2 | B82: USLAX | C82: Amazon.com Services LLC | D82: 6401 Howdy Wells Ave LAS VEGAS, Nevada 89115 | E82: LAS VEGAS | F82: NV | G82: 89115 | H82: US | I82: Sort | J82: SMP/GWD/AMP 2.0 (rIXD) | K82: NORTH_CENTRAL
...
